<?xml version="1.0" ?>
<robot name="golf_swing_model">
  <material name="gray">
    <color rgba="0.5 0.5 0.5 1.0"/>
  </material>
  <link name="pelvis">
    <inertial>
      <mass value="15"/>
      <origin xyz="0 0 0" rpy="0 0 0"/>
      <inertia ixx="0.1" iyy="0.1625" izz="0.1625" ixy="0" ixz="0" iyz="0"/>
    </inertial>
    <visual>
      <origin xyz="0 0 0" rpy="0 0 0"/>
      <geometry>
        <box size="0.3 0.2 0.2"/>
      </geometry>
      <material name="gray"/>
    </visual>
    <collision>
      <origin xyz="0 0 0" rpy="0 0 0"/>
      <geometry>
        <box size="0.3 0.2 0.2"/>
      </geometry>
    </collision>
  </link>
  <link name="spine_base">
    <inertial>
      <mass value="1"/>
      <origin xyz="0 0 0" rpy="0 0 0"/>
      <inertia ixx="0.00166667" iyy="0.00166667" izz="0.00166667" ixy="0" ixz="0" iyz="0"/>
    </inertial>
    <visual>
      <origin xyz="0 0 0" rpy="0 0 0"/>
      <geometry>
        <box size="0.1 0.1 0.1"/>
      </geometry>
      <material name="gray"/>
    </visual>
    <collision>
      <origin xyz="0 0 0" rpy="0 0 0"/>
      <geometry>
        <box size="0.1 0.1 0.1"/>
      </geometry>
    </collision>
  </link>
  <joint name="hip_yaw" type="revolute">
    <parent link="pelvis"/>
    <child link="spine_base"/>
    <origin xyz="0 0 0" rpy="0 -0 0"/>
    <axis xyz="0 0 1"/>
  </joint>
  <link name="spine_dummy">
    <inertial>
      <mass value="0.01"/>
      <origin xyz="0 0 0" rpy="0 0 0"/>
      <inertia ixx="4e-07" iyy="4e-07" izz="4e-07" ixy="0" ixz="0" iyz="0"/>
    </inertial>
  </link>
  <link name="lower_spine">
    <inertial>
      <mass value="7.5"/>
      <origin xyz="0 0 0" rpy="0 0 0"/>
      <inertia ixx="0.0441406" iyy="0.0441406" izz="0.05" ixy="0" ixz="0" iyz="0"/>
    </inertial>
    <visual>
      <origin xyz="0 0 0" rpy="0 0 0"/>
      <geometry>
        <box size="0.2 0.2 0.175"/>
      </geometry>
      <material name="gray"/>
    </visual>
    <collision>
      <origin xyz="0 0 0" rpy="0 0 0"/>
      <geometry>
        <box size="0.2 0.2 0.175"/>
      </geometry>
    </collision>
  </link>
  <joint name="spine_universal_1" type="revolute">
    <parent link="spine_base"/>
    <child link="spine_dummy"/>
    <origin xyz="0 0 0" rpy="0 -0 0"/>
    <axis xyz="1 0 0"/>
  </joint>
  <joint name="spine_universal_2" type="revolute">
    <parent link="spine_dummy"/>
    <child link="lower_spine"/>
    <origin xyz="0 0 0" rpy="0 -0 0"/>
    <axis xyz="0 1 0"/>
  </joint>
  <link name="upper_spine">
    <inertial>
      <mass value="7.5"/>
      <origin xyz="0 0 0.0875" rpy="0 0 0"/>
      <inertia ixx="0.0441406" iyy="0.0441406" izz="0.05" ixy="0" ixz="0" iyz="0"/>
    </inertial>
    <visual>
      <origin xyz="0 0 0.0875" rpy="0 0 0"/>
      <geometry>
        <box size="0.2 0.2 0.175"/>
      </geometry>
      <material name="gray"/>
    </visual>
    <collision>
      <origin xyz="0 0 0.0875" rpy="0 0 0"/>
      <geometry>
        <box size="0.2 0.2 0.175"/>
      </geometry>
    </collision>
  </link>
  <joint name="spine_twist" type="revolute">
    <parent link="lower_spine"/>
    <child link="upper_spine"/>
    <origin xyz="0 0 0.0875" rpy="0 -0 0"/>
    <axis xyz="0 0 1"/>
  </joint>
  <link name="upper_torso_hub">
    <inertial>
      <mass value="5"/>
      <origin xyz="0 0 0" rpy="0 0 0"/>
      <inertia ixx="0.0541667" iyy="0.0541667" izz="0.075" ixy="0" ixz="0" iyz="0"/>
    </inertial>
    <visual>
      <origin xyz="0 0 0" rpy="0 0 0"/>
      <geometry>
        <box size="0.3 0.3 0.2"/>
      </geometry>
      <material name="gray"/>
    </visual>
    <collision>
      <origin xyz="0 0 0" rpy="0 0 0"/>
      <geometry>
        <box size="0.3 0.3 0.2"/>
      </geometry>
    </collision>
  </link>
  <joint name="torso_weld" type="fixed">
    <parent link="upper_spine"/>
    <child link="upper_torso_hub"/>
    <origin xyz="0 0 0.175" rpy="0 -0 0"/>
  </joint>
  <link name="left_scapula_dummy">
    <inertial>
      <mass value="0.01"/>
      <origin xyz="0 0 0" rpy="0 0 0"/>
      <inertia ixx="4e-07" iyy="4e-07" izz="4e-07" ixy="0" ixz="0" iyz="0"/>
    </inertial>
  </link>
  <link name="left_scapula_rod">
    <inertial>
      <mass value="1"/>
      <origin xyz="0 0 0.06" rpy="0 0 0"/>
      <inertia ixx="0.001425" iyy="0.001425" izz="0.00045" ixy="0" ixz="0" iyz="0"/>
    </inertial>
    <visual>
      <origin xyz="0 0 0.06" rpy="0 0 0"/>
      <geometry>
        <cylinder length="0.12" radius="0.03"/>
      </geometry>
      <material name="gray"/>
    </visual>
    <collision>
      <origin xyz="0 0 0.06" rpy="0 0 0"/>
      <geometry>
        <cylinder length="0.12" radius="0.03"/>
      </geometry>
    </collision>
  </link>
  <joint name="left_scapula_universal_1" type="revolute">
    <parent link="upper_torso_hub"/>
    <child link="left_scapula_dummy"/>
    <origin xyz="0 -0.18 0.1" rpy="0 -0 0"/>
    <axis xyz="1 0 0"/>
  </joint>
  <joint name="left_scapula_universal_2" type="revolute">
    <parent link="left_scapula_dummy"/>
    <child link="left_scapula_rod"/>
    <origin xyz="0 0 0" rpy="0 -0 0"/>
    <axis xyz="0 1 0"/>
  </joint>
  <link name="left_shoulder_yaw_link">
    <inertial>
      <mass value="0.1"/>
      <origin xyz="0 0 0" rpy="0 0 0"/>
      <inertia ixx="0.0001" iyy="0.0001" izz="0.0001" ixy="0" ixz="0" iyz="0"/>
    </inertial>
    <visual>
      <origin xyz="0 0 0" rpy="0 0 0"/>
      <geometry>
        <sphere radius="0.05"/>
      </geometry>
      <material name="gray"/>
    </visual>
    <collision>
      <origin xyz="0 0 0" rpy="0 0 0"/>
      <geometry>
        <sphere radius="0.05"/>
      </geometry>
    </collision>
  </link>
  <joint name="left_shoulder_yaw" type="revolute">
    <parent link="left_scapula_rod"/>
    <child link="left_shoulder_yaw_link"/>
    <origin xyz="0 0 0.12" rpy="0 -0 0"/>
    <axis xyz="0 0 1"/>
  </joint>
  <link name="left_shoulder_pitch_link">
    <inertial>
      <mass value="0.1"/>
      <origin xyz="0 0 0" rpy="0 0 0"/>
      <inertia ixx="0.0001" iyy="0.0001" izz="0.0001" ixy="0" ixz="0" iyz="0"/>
    </inertial>
    <visual>
      <origin xyz="0 0 0" rpy="0 0 0"/>
      <geometry>
        <sphere radius="0.05"/>
      </geometry>
      <material name="gray"/>
    </visual>
    <collision>
      <origin xyz="0 0 0" rpy="0 0 0"/>
      <geometry>
        <sphere radius="0.05"/>
      </geometry>
    </collision>
  </link>
  <joint name="left_shoulder_pitch" type="revolute">
    <parent link="left_shoulder_yaw_link"/>
    <child link="left_shoulder_pitch_link"/>
    <origin xyz="0 0 0" rpy="0 -0 0"/>
    <axis xyz="0 1 0"/>
  </joint>
  <link name="left_shoulder_roll_link">
    <inertial>
      <mass value="0.1"/>
      <origin xyz="0 0 0" rpy="0 0 0"/>
      <inertia ixx="0.0001" iyy="0.0001" izz="0.0001" ixy="0" ixz="0" iyz="0"/>
    </inertial>
    <visual>
      <origin xyz="0 0 0" rpy="0 0 0"/>
      <geometry>
        <sphere radius="0.05"/>
      </geometry>
      <material name="gray"/>
    </visual>
    <collision>
      <origin xyz="0 0 0" rpy="0 0 0"/>
      <geometry>
        <sphere radius="0.05"/>
      </geometry>
    </collision>
  </link>
  <joint name="left_shoulder_roll" type="revolute">
    <parent link="left_shoulder_pitch_link"/>
    <child link="left_shoulder_roll_link"/>
    <origin xyz="0 0 0" rpy="0 -0 0"/>
    <axis xyz="1 0 0"/>
  </joint>
  <link name="left_upper_arm">
    <inertial>
      <mass value="2"/>
      <origin xyz="0 0 0" rpy="0 0 0"/>
      <inertia ixx="0.01545" iyy="0.01545" izz="0.0009" ixy="0" ixz="0" iyz="0"/>
    </inertial>
    <visual>
      <origin xyz="0 0 0" rpy="0 0 0"/>
      <geometry>
        <cylinder length="0.3" radius="0.03"/>
      </geometry>
      <material name="gray"/>
    </visual>
    <collision>
      <origin xyz="0 0 0" rpy="0 0 0"/>
      <geometry>
        <cylinder length="0.3" radius="0.03"/>
      </geometry>
    </collision>
  </link>
  <joint name="left_upper_arm_weld" type="fixed">
    <parent link="left_shoulder_roll_link"/>
    <child link="left_upper_arm"/>
    <origin xyz="0 0 -0.15" rpy="0 -0 0"/>
  </joint>
  <joint name="left_elbow" type="revolute">
    <parent link="left_upper_arm"/>
    <child link="left_forearm"/>
    <origin xyz="0 0 -0.15" rpy="0 -0 0"/>
    <axis xyz="0 1 0"/>
  </joint>
  <link name="left_forearm">
    <inertial>
      <mass value="1.5"/>
      <origin xyz="0 0 0.135" rpy="0 0 0"/>
      <inertia ixx="0.00945" iyy="0.00945" izz="0.000675" ixy="0" ixz="0" iyz="0"/>
    </inertial>
    <visual>
      <origin xyz="0 0 0.135" rpy="0 0 0"/>
      <geometry>
        <cylinder length="0.27" radius="0.03"/>
      </geometry>
      <material name="gray"/>
    </visual>
    <collision>
      <origin xyz="0 0 0.135" rpy="0 0 0"/>
      <geometry>
        <cylinder length="0.27" radius="0.03"/>
      </geometry>
    </collision>
  </link>
  <link name="left_wrist_dummy">
    <inertial>
      <mass value="0.01"/>
      <origin xyz="0 0 0" rpy="0 0 0"/>
      <inertia ixx="4e-07" iyy="4e-07" izz="4e-07" ixy="0" ixz="0" iyz="0"/>
    </inertial>
  </link>
  <link name="left_hand">
    <inertial>
      <mass value="0.5"/>
      <origin xyz="0 0 0.05" rpy="0 0 0"/>
      <inertia ixx="0.000529167" iyy="0.000529167" izz="0.000225" ixy="0" ixz="0" iyz="0"/>
    </inertial>
    <visual>
      <origin xyz="0 0 0.05" rpy="0 0 0"/>
      <geometry>
        <cylinder length="0.1" radius="0.03"/>
      </geometry>
      <material name="gray"/>
    </visual>
    <collision>
      <origin xyz="0 0 0.05" rpy="0 0 0"/>
      <geometry>
        <cylinder length="0.1" radius="0.03"/>
      </geometry>
    </collision>
  </link>
  <joint name="left_wrist_universal_1" type="revolute">
    <parent link="left_forearm"/>
    <child link="left_wrist_dummy"/>
    <origin xyz="0 0 0.27" rpy="0 -0 0"/>
    <axis xyz="1 0 0"/>
  </joint>
  <joint name="left_wrist_universal_2" type="revolute">
    <parent link="left_wrist_dummy"/>
    <child link="left_hand"/>
    <origin xyz="0 0 0" rpy="0 -0 0"/>
    <axis xyz="0 1 0"/>
  </joint>
  <link name="right_scapula_dummy">
    <inertial>
      <mass value="0.01"/>
      <origin xyz="0 0 0" rpy="0 0 0"/>
      <inertia ixx="4e-07" iyy="4e-07" izz="4e-07" ixy="0" ixz="0" iyz="0"/>
    </inertial>
  </link>
  <link name="right_scapula_rod">
    <inertial>
      <mass value="1"/>
      <origin xyz="0 0 0.06" rpy="0 0 0"/>
      <inertia ixx="0.001425" iyy="0.001425" izz="0.00045" ixy="0" ixz="0" iyz="0"/>
    </inertial>
    <visual>
      <origin xyz="0 0 0.06" rpy="0 0 0"/>
      <geometry>
        <cylinder length="0.12" radius="0.03"/>
      </geometry>
      <material name="gray"/>
    </visual>
    <collision>
      <origin xyz="0 0 0.06" rpy="0 0 0"/>
      <geometry>
        <cylinder length="0.12" radius="0.03"/>
      </geometry>
    </collision>
  </link>
  <joint name="right_scapula_universal_1" type="revolute">
    <parent link="upper_torso_hub"/>
    <child link="right_scapula_dummy"/>
    <origin xyz="0 0.18 0.1" rpy="0 -0 0"/>
    <axis xyz="1 0 0"/>
  </joint>
  <joint name="right_scapula_universal_2" type="revolute">
    <parent link="right_scapula_dummy"/>
    <child link="right_scapula_rod"/>
    <origin xyz="0 0 0" rpy="0 -0 0"/>
    <axis xyz="0 1 0"/>
  </joint>
  <link name="right_shoulder_yaw_link">
    <inertial>
      <mass value="0.1"/>
      <origin xyz="0 0 0" rpy="0 0 0"/>
      <inertia ixx="0.0001" iyy="0.0001" izz="0.0001" ixy="0" ixz="0" iyz="0"/>
    </inertial>
    <visual>
      <origin xyz="0 0 0" rpy="0 0 0"/>
      <geometry>
        <sphere radius="0.05"/>
      </geometry>
      <material name="gray"/>
    </visual>
    <collision>
      <origin xyz="0 0 0" rpy="0 0 0"/>
      <geometry>
        <sphere radius="0.05"/>
      </geometry>
    </collision>
  </link>
  <joint name="right_shoulder_yaw" type="revolute">
    <parent link="right_scapula_rod"/>
    <child link="right_shoulder_yaw_link"/>
    <origin xyz="0 0 0.12" rpy="0 -0 0"/>
    <axis xyz="0 0 1"/>
  </joint>
  <link name="right_shoulder_pitch_link">
    <inertial>
      <mass value="0.1"/>
      <origin xyz="0 0 0" rpy="0 0 0"/>
      <inertia ixx="0.0001" iyy="0.0001" izz="0.0001" ixy="0" ixz="0" iyz="0"/>
    </inertial>
    <visual>
      <origin xyz="0 0 0" rpy="0 0 0"/>
      <geometry>
        <sphere radius="0.05"/>
      </geometry>
      <material name="gray"/>
    </visual>
    <collision>
      <origin xyz="0 0 0" rpy="0 0 0"/>
      <geometry>
        <sphere radius="0.05"/>
      </geometry>
    </collision>
  </link>
  <joint name="right_shoulder_pitch" type="revolute">
    <parent link="right_shoulder_yaw_link"/>
    <child link="right_shoulder_pitch_link"/>
    <origin xyz="0 0 0" rpy="0 -0 0"/>
    <axis xyz="0 1 0"/>
  </joint>
  <link name="right_shoulder_roll_link">
    <inertial>
      <mass value="0.1"/>
      <origin xyz="0 0 0" rpy="0 0 0"/>
      <inertia ixx="0.0001" iyy="0.0001" izz="0.0001" ixy="0" ixz="0" iyz="0"/>
    </inertial>
    <visual>
      <origin xyz="0 0 0" rpy="0 0 0"/>
      <geometry>
        <sphere radius="0.05"/>
      </geometry>
      <material name="gray"/>
    </visual>
    <collision>
      <origin xyz="0 0 0" rpy="0 0 0"/>
      <geometry>
        <sphere radius="0.05"/>
      </geometry>
    </collision>
  </link>
  <joint name="right_shoulder_roll" type="revolute">
    <parent link="right_shoulder_pitch_link"/>
    <child link="right_shoulder_roll_link"/>
    <origin xyz="0 0 0" rpy="0 -0 0"/>
    <axis xyz="1 0 0"/>
  </joint>
  <link name="right_upper_arm">
    <inertial>
      <mass value="2"/>
      <origin xyz="0 0 0" rpy="0 0 0"/>
      <inertia ixx="0.01545" iyy="0.01545" izz="0.0009" ixy="0" ixz="0" iyz="0"/>
    </inertial>
    <visual>
      <origin xyz="0 0 0" rpy="0 0 0"/>
      <geometry>
        <cylinder length="0.3" radius="0.03"/>
      </geometry>
      <material name="gray"/>
    </visual>
    <collision>
      <origin xyz="0 0 0" rpy="0 0 0"/>
      <geometry>
        <cylinder length="0.3" radius="0.03"/>
      </geometry>
    </collision>
  </link>
  <joint name="right_upper_arm_weld" type="fixed">
    <parent link="right_shoulder_roll_link"/>
    <child link="right_upper_arm"/>
    <origin xyz="0 0 -0.15" rpy="0 -0 0"/>
  </joint>
  <joint name="right_elbow" type="revolute">
    <parent link="right_upper_arm"/>
    <child link="right_forearm"/>
    <origin xyz="0 0 -0.15" rpy="0 -0 0"/>
    <axis xyz="0 1 0"/>
  </joint>
  <link name="right_forearm">
    <inertial>
      <mass value="1.5"/>
      <origin xyz="0 0 0.135" rpy="0 0 0"/>
      <inertia ixx="0.00945" iyy="0.00945" izz="0.000675" ixy="0" ixz="0" iyz="0"/>
    </inertial>
    <visual>
      <origin xyz="0 0 0.135" rpy="0 0 0"/>
      <geometry>
        <cylinder length="0.27" radius="0.03"/>
      </geometry>
      <material name="gray"/>
    </visual>
    <collision>
      <origin xyz="0 0 0.135" rpy="0 0 0"/>
      <geometry>
        <cylinder length="0.27" radius="0.03"/>
      </geometry>
    </collision>
  </link>
  <link name="right_wrist_dummy">
    <inertial>
      <mass value="0.01"/>
      <origin xyz="0 0 0" rpy="0 0 0"/>
      <inertia ixx="4e-07" iyy="4e-07" izz="4e-07" ixy="0" ixz="0" iyz="0"/>
    </inertial>
  </link>
  <link name="right_hand">
    <inertial>
      <mass value="0.5"/>
      <origin xyz="0 0 0.05" rpy="0 0 0"/>
      <inertia ixx="0.000529167" iyy="0.000529167" izz="0.000225" ixy="0" ixz="0" iyz="0"/>
    </inertial>
    <visual>
      <origin xyz="0 0 0.05" rpy="0 0 0"/>
      <geometry>
        <cylinder length="0.1" radius="0.03"/>
      </geometry>
      <material name="gray"/>
    </visual>
    <collision>
      <origin xyz="0 0 0.05" rpy="0 0 0"/>
      <geometry>
        <cylinder length="0.1" radius="0.03"/>
      </geometry>
    </collision>
  </link>
  <joint name="right_wrist_universal_1" type="revolute">
    <parent link="right_forearm"/>
    <child link="right_wrist_dummy"/>
    <origin xyz="0 0 0.27" rpy="0 -0 0"/>
    <axis xyz="1 0 0"/>
  </joint>
  <joint name="right_wrist_universal_2" type="revolute">
    <parent link="right_wrist_dummy"/>
    <child link="right_hand"/>
    <origin xyz="0 0 0" rpy="0 -0 0"/>
    <axis xyz="0 1 0"/>
  </joint>
  <link name="club">
    <inertial>
      <mass value="0.4"/>
      <origin xyz="0 0 0.525" rpy="0 0 0"/>
      <inertia ixx="0.03684" iyy="0.03684" izz="0.00018" ixy="0" ixz="0" iyz="0"/>
    </inertial>
    <visual>
      <origin xyz="0 0 0.525" rpy="0 0 0"/>
      <geometry>
        <cylinder length="1.05" radius="0.03"/>
      </geometry>
      <material name="gray"/>
    </visual>
    <collision>
      <origin xyz="0 0 0.525" rpy="0 0 0"/>
      <geometry>
        <cylinder length="1.05" radius="0.03"/>
      </geometry>
    </collision>
  </link>
  <joint name="grip_lead" type="fixed">
    <parent link="left_hand"/>
    <child link="club"/>
    <origin xyz="0 0 0.1" rpy="0 -0 0"/>
  </joint>
</robot>
